<?xml version="1.0"?>
<sdf version="1.6">
	<model name='simple_robot'>
		<pose>0 0 0.325 0 -0 0</pose>
		<link name='chassis'>
			<pose>-0.151427 -0 0.175 0 -0 0</pose>
			<inertial>
				<mass>1.14395</mass>
				<inertia>
					<ixx>0.126164</ixx>
					<ixy>0</ixy>
					<ixz>0</ixz>
					<iyy>0.416519</iyy>
					<iyz>0</iyz>
					<izz>0.481014</izz>
				</inertia>
			</inertial>
			<visual name='visual'>
				<geometry>
					<box>
						<size>2.01142 1 0.568726</size>
					</box>
				</geometry>
				<material>
					<ambient>0.5 0.5 0.5 1</ambient>
					<diffuse>0.5 0.5 0.5 1</diffuse>
					<specular>0.5 0.5 0.5 1</specular>
				</material>
			</visual>
			<collision name='collision'>
				<geometry>
					<box>
						<size>2.01142 1 0.568726</size>
					</box>
				</geometry>
			</collision>
		</link>

		<link name='left_wheel'>
			<pose>0.554283 0.625029 -0.025 -1.5707 0 0</pose>
			<inertial>
				<mass>2</mass>
				<inertia>
					<ixx>0.145833</ixx>
					<ixy>0</ixy>
					<ixz>0</ixz>
					<iyy>0.145833</iyy>
					<iyz>0</iyz>
					<izz>0.125</izz>
				</inertia>
			</inertial>
			<visual name='visual'>
				<geometry>
					<sphere>
						<radius>0.3</radius>
					</sphere>
				</geometry>
				<material>
					<ambient>0.2 0.2 0.2 1</ambient>
					<diffuse>0.2 0.2 0.2 1</diffuse>
					<specular>0.2 0.2 0.2 1</specular>
				</material>
			</visual>
			<collision name='collision'>
				<geometry>
					<sphere>
						<radius>0.3</radius>
					</sphere>
				</geometry>
			</collision>
		</link>

		<link name='right_wheel'>
			<pose>0.554282 -0.625029 -0.025 -1.5707 0 0</pose>
			<inertial>
				<mass>2</mass>
				<inertia>
					<ixx>0.145833</ixx>
					<ixy>0</ixy>
					<ixz>0</ixz>
					<iyy>0.145833</iyy>
					<iyz>0</iyz>
					<izz>0.125</izz>
				</inertia>
			</inertial>
			<visual name='visual'>
				<geometry>
					<sphere>
						<radius>0.3</radius>
					</sphere>
				</geometry>
				<material>
					<ambient>0.2 0.2 0.2 1</ambient>
					<diffuse>0.2 0.2 0.2 1</diffuse>
					<specular>0.2 0.2 0.2 1</specular>
				</material>
			</visual>
			<collision name='collision'>
				<geometry>
					<sphere>
						<radius>0.3</radius>
					</sphere>
				</geometry>
			</collision>
		</link>

		<link name='caster'>
			<pose>-0.957138 -0 -0.125 0 -0 0</pose>
			<inertial>
				<mass>1</mass>
				<inertia>
					<ixx>0.1</ixx>
					<ixy>0</ixy>
					<ixz>0</ixz>
					<iyy>0.1</iyy>
					<iyz>0</iyz>
					<izz>0.1</izz>
				</inertia>
			</inertial>
			<visual name='visual'>
				<geometry>
					<sphere>
						<radius>0.2</radius>
					</sphere>
				</geometry>
				<material>
					<ambient>0.2 0.2 0.2 1</ambient>
					<diffuse>0.2 0.2 0.2 1</diffuse>
					<specular>0.2 0.2 0.2 1</specular>
				</material>
			</visual>
			<collision name='collision'>
				<geometry>
					<sphere>
						<radius>0.2</radius>
					</sphere>
				</geometry>
			</collision>
		</link>

		<link name="camera">
			<pose>0.85 0 0.25 0 0 0</pose>
			<inertial>
				<mass>0.1</mass>
				<inertia>
					<ixx>0.000166667</ixx>
					<iyy>0.000166667</iyy>
					<izz>0.000166667</izz>
				</inertia>
			</inertial>
			<collision name="collision">
				<geometry>
					<box>
						<size>0.1 0.1 0.1</size>
					</box>
				</geometry>
			</collision>
			<visual name="visual">
				<geometry>
					<box>
						<size>0.1 0.1 0.1</size>
					</box>
				</geometry>
				<material>
					<ambient>0.2 0.2 0.2 1</ambient>
					<diffuse>0.2 0.2 0.2 1</diffuse>
					<specular>0.2 0.2 0.2 1</specular>
				</material>
			</visual>
			<sensor name="camera" type="camera">
				<camera>
					<horizontal_fov>1.047</horizontal_fov>
					<image>
						<width>320</width>
						<height>240</height>
					</image>
					<clip>
						<near>0.1</near>
						<far>100</far>
					</clip>
				</camera>
				<always_on>1</always_on>
				<update_rate>30</update_rate>
				<visualize>true</visualize>
				<topic>camera</topic>
			</sensor>
		</link>

		<joint name='left_wheel_joint' type='revolute'>
			<parent>chassis</parent>
			<child>left_wheel</child>
			<axis>
				<xyz>0 0 1</xyz>
				<limit>
					<lower>-1.79769e+308</lower>
					<upper>1.79769e+308</upper>
				</limit>
			</axis>
		</joint>

		<joint name='right_wheel_joint' type='revolute'>
			<parent>chassis</parent>
			<child>right_wheel</child>
			<axis>
				<xyz>0 0 1</xyz>
				<limit>
					<lower>-1.79769e+308</lower>
					<upper>1.79769e+308</upper>
				</limit>
			</axis>
		</joint>

		<joint name='caster_wheel' type='ball'>
			<parent>chassis</parent>
			<child>caster</child>
		</joint>

		<joint name='camera_joint' type='fixed'>
			<parent>chassis</parent>
			<child>camera</child>
		</joint>

		<!--diff drive plugin-->
		<plugin
			filename="gz-sim-diff-drive-system"
			name="gz::sim::systems::DiffDrive">
			<left_joint>left_wheel_joint</left_joint>
			<right_joint>right_wheel_joint</right_joint>
			<wheel_separation>1.25</wheel_separation>
			<wheel_radius>0.3</wheel_radius>
			<odom_publish_frequency>1</odom_publish_frequency>
			<topic>cmd_vel</topic>
		</plugin>
	</model>
</sdf>
